<mujoco model="doggo_walker">
    <compiler inertiafromgeom="true" angle="radian"/>

    <default>
        <joint limited="true" damping="0" armature="0"/>
        <geom condim="1" material="matgeom"/>
        <motor ctrlrange="-.4 .4" ctrllimited="true"/>
    </default>

    <option timestep="0.005" iterations="50" tolerance="1e-10" solver="Newton" jacobian="dense" cone="pyramidal"/>
    <!-- <size njmax="500" nconmax="100" nstack="10000" /> -->
    <size nconmax="50" njmax="200" nstack="10000"/>

    <visual>
        <map force="0.1" zfar="30"/>
        <rgba haze="0.15 0.25 0.35 1"/>
        <quality shadowsize="2048"/>
        <global offwidth="800" offheight="800"/>
    </visual>

    <asset>
        <mesh name="body" file="body.stl" />
        <mesh name="femur" file="femur.stl" />
        <mesh name="lower_leg" file="lower_leg.stl" />

        <texture type="skybox" builtin="gradient" rgb1="0.3 0.5 0.7" rgb2="0 0 0" width="512" height="512"/> 
        <texture name="texplane" type="2d" builtin="checker" rgb1=".2 .3 .4" rgb2=".1 0.15 0.2" width="512" height="512" mark="cross" markrgb=".8 .8 .8"/>  
        <texture name="texgeom" type="cube" builtin="flat" mark="cross" width="127" height="1278" 
            rgb1="0.8 0.6 0.4" rgb2="0.8 0.6 0.4" markrgb="1 1 1" random="0.01"/>  
        <material name="matplane" reflectance="0.3" texture="texplane" texrepeat="1 1" texuniform="true"/>
        <material name="matgeom" texture="texgeom" texuniform="true" rgba="0.8 0.6 .4 1"/>
    </asset>
    <worldbody >
        <geom name="floor" pos="0 0 -0.27" size="0 0 .25" type="plane" material="matplane" condim="3"/>

        <light directional="false" diffuse=".2 .2 .2" specular="0 0 0" pos="0 0 5" dir="0 0 -1" castshadow="false"/>
        <!-- <light mode="targetbodycom" target="body" directional="false" diffuse=".8 .8 .8" specular="0.3 0.3 0.3" pos="0 0 4.0" dir="0 0 -1"/>  -->

        <geom type="mesh" rgba="0.79216 0.81961 0.93333 1" mesh="body" />
        <!-- <freejoint name="root"/> -->
        <body name="front_right_femur" pos="0.13 -0.12 0">
            <inertial pos="0 0 -0.055" quat="-7.20094e-05 0.707107 0.707107 -7.20094e-05" mass="0.4" diaginertia="0.00135004 0.00135004 0.000266667" />
            <joint name="FRFJ" pos="0 0 0" axis="0 1 0" limited="true" range="-0.7 0.7" />
            <geom pos="0 0 -0.055" quat="0.707035 0 0 0.707179" type="mesh" rgba="0.79216 0.81961 0.93333 1" mesh="femur" />
            <body name="front_right_lower_leg" pos="0 0 -0.115">
                <inertial pos="0 0 -0.084" quat="1 0 7.15163e-05 0" mass="0.5" diaginertia="0.000980247 0.00081992 0.000436139" />
                <joint name="FRLLJ" pos="0 0 0" axis="0 1 0" limited="true" range="-1.2 1.2" />
                <geom pos="0 0 -0.075" quat="0.707035 0 0 0.707179" type="mesh" rgba="0.79216 0.81961 0.93333 1" mesh="lower_leg" />
                <geom size="0.03" pos="0 0 -0.12" rgba="0.79216 0.81961 0.93333 1" />
            </body>
        </body>
        <body name="front_left_femur" pos="0.13 0.12 0">
            <inertial pos="0 0 -0.055" quat="-7.20094e-05 0.707107 0.707107 -7.20094e-05" mass="0.4" diaginertia="0.00135004 0.00135004 0.000266667" />
            <joint name="FLFJ" pos="0 0 0" axis="0 1 0" limited="true" range="-0.7 0.7" />
            <geom pos="0 0 -0.055" quat="0.707035 0 0 0.707179" type="mesh" rgba="0.79216 0.81961 0.93333 1" mesh="femur" />
            <body name="front_left_lower_leg" pos="0 0 -0.115">
                <inertial pos="0 0 -0.084" quat="1 0 7.15163e-05 0" mass="0.5" diaginertia="0.000980247 0.00081992 0.000436139" />
                <joint name="FLLLJ" pos="0 0 0" axis="0 1 0" limited="true" range="-1.2 1.2" />
                <geom pos="0 0 -0.075" quat="0.707035 0 0 0.707179" type="mesh" rgba="0.79216 0.81961 0.93333 1" mesh="lower_leg" />
                <geom size="0.03" pos="0 0 -0.12" rgba="0.79216 0.81961 0.93333 1" />
            </body>
        </body>
        <body name="rear_right_femur" pos="-0.13 -0.12 0">
            <inertial pos="0 0 -0.055" quat="-7.20094e-05 0.707107 0.707107 -7.20094e-05" mass="0.4" diaginertia="0.00135004 0.00135004 0.000266667" />
            <joint name="RRFJ" pos="0 0 0" axis="0 1 0" limited="true" range="-0.7 0.7" />
            <geom pos="0 0 -0.055" quat="0.707035 0 0 0.707179" type="mesh" rgba="0.79216 0.81961 0.93333 1" mesh="femur" />
            <body name="rear_right_lower_leg" pos="0 0 -0.115">
                <inertial pos="0 0 -0.084" quat="1 0 7.15163e-05 0" mass="0.5" diaginertia="0.000980247 0.00081992 0.000436139" />
                <joint name="RRLLJ" pos="0 0 0" axis="0 1 0" limited="true" range="-1.2 1.2" />
                <geom pos="0 0 -0.075" quat="0.707035 0 0 0.707179" type="mesh" rgba="0.79216 0.81961 0.93333 1" mesh="lower_leg" />
                <geom size="0.03" pos="0 0 -0.12" rgba="0.79216 0.81961 0.93333 1" />
            </body>
        </body>
        <body name="rear_left_femur" pos="-0.13 0.12 0">
            <inertial pos="0 0 -0.055" quat="-7.20094e-05 0.707107 0.707107 -7.20094e-05" mass="0.4" diaginertia="0.00135004 0.00135004 0.000266667" />
            <joint name="RLFJ" pos="0 0 0" axis="0 1 0" limited="true" range="-0.7 0.7" />
            <geom pos="0 0 -0.055" quat="0.707035 0 0 0.707179" type="mesh" rgba="0.79216 0.81961 0.93333 1" mesh="femur" />
            <body name="rear_left_lower_leg" pos="0 0 -0.115">
                <inertial pos="0 0 -0.084" quat="1 0 7.15163e-05 0" mass="0.5" diaginertia="0.000980247 0.00081992 0.000436139" />
                <joint name="RLLLJ" pos="0 0 0" axis="0 1 0" limited="true" range="-1.2 1.2" />
                <geom pos="0 0 -0.075" quat="0.707035 0 0 0.707179" type="mesh" rgba="0.79216 0.81961 0.93333 1" mesh="lower_leg" />
                <geom size="0.03" pos="0 0 -0.12" rgba="0.79216 0.81961 0.93333 1" />
            </body>
        </body>
    </worldbody>


    <actuator>
        <motor name="right_hip_x"     gear="3" joint="FRFJ" />
        <motor name="right_hip_z"     gear="3" joint="FRLLJ" />
        <motor name="right_hip_y"     gear="3" joint="FLFJ" />
        <motor name="knee_right"      gear="3" joint="FLLLJ" />
        <motor name="left_hip_x"      gear="3" joint="RRFJ" />
        <motor name="left_hip_z"      gear="3" joint="RRLLJ" />
        <motor name="left_hip_y"      gear="3" joint="RLFJ" />
        <motor name="knee_left"       gear="3" joint="RLLLJ" />
    </actuator>

</mujoco>
